{
 "cells": [
  {
   "cell_type": "code",
   "execution_count": 20,
   "metadata": {},
   "outputs": [],
   "source": [
    "from time import sleep\n",
    "import asyncio\n",
    "async def asyncFunction(n:int, s:int):\n",
    "    await print(f'function{n} start')\n",
    "    await asyncio.sleep(s)\n",
    "    await print(f'function{n} end')"
   ]
  },
  {
   "cell_type": "code",
   "execution_count": 21,
   "metadata": {},
   "outputs": [],
   "source": [
    "def standerdFunction(n:int, s:int):\n",
    "    print(f'standerd function {n} start')\n",
    "    sleep(s)\n",
    "    print(f'starderd function {n} end')"
   ]
  },
  {
   "cell_type": "code",
   "execution_count": 22,
   "metadata": {},
   "outputs": [
    {
     "ename": "RuntimeError",
     "evalue": "This event loop is already running",
     "output_type": "error",
     "traceback": [
      "\u001b[1;31m---------------------------------------------------------------------------\u001b[0m",
      "\u001b[1;31mRuntimeError\u001b[0m                              Traceback (most recent call last)",
      "Cell \u001b[1;32mIn[22], line 3\u001b[0m\n\u001b[0;32m      1\u001b[0m loop \u001b[38;5;241m=\u001b[39m asyncio\u001b[38;5;241m.\u001b[39mget_event_loop()\n\u001b[0;32m      2\u001b[0m loop\u001b[38;5;241m.\u001b[39mcreate_task(asyncFunction(\u001b[38;5;241m1\u001b[39m, \u001b[38;5;241m3\u001b[39m))\n\u001b[1;32m----> 3\u001b[0m \u001b[43mloop\u001b[49m\u001b[38;5;241;43m.\u001b[39;49m\u001b[43mrun_until_complete\u001b[49m\u001b[43m(\u001b[49m\u001b[43masyncFunction\u001b[49m\u001b[43m(\u001b[49m\u001b[38;5;241;43m2\u001b[39;49m\u001b[43m,\u001b[49m\u001b[43m \u001b[49m\u001b[38;5;241;43m3\u001b[39;49m\u001b[43m)\u001b[49m\u001b[43m)\u001b[49m\n",
      "File \u001b[1;32mc:\\Users\\TP23018\\AppData\\Local\\Programs\\Python\\Python312\\Lib\\asyncio\\base_events.py:663\u001b[0m, in \u001b[0;36mBaseEventLoop.run_until_complete\u001b[1;34m(self, future)\u001b[0m\n\u001b[0;32m    652\u001b[0m \u001b[38;5;250m\u001b[39m\u001b[38;5;124;03m\"\"\"Run until the Future is done.\u001b[39;00m\n\u001b[0;32m    653\u001b[0m \n\u001b[0;32m    654\u001b[0m \u001b[38;5;124;03mIf the argument is a coroutine, it is wrapped in a Task.\u001b[39;00m\n\u001b[1;32m   (...)\u001b[0m\n\u001b[0;32m    660\u001b[0m \u001b[38;5;124;03mReturn the Future's result, or raise its exception.\u001b[39;00m\n\u001b[0;32m    661\u001b[0m \u001b[38;5;124;03m\"\"\"\u001b[39;00m\n\u001b[0;32m    662\u001b[0m \u001b[38;5;28mself\u001b[39m\u001b[38;5;241m.\u001b[39m_check_closed()\n\u001b[1;32m--> 663\u001b[0m \u001b[38;5;28;43mself\u001b[39;49m\u001b[38;5;241;43m.\u001b[39;49m\u001b[43m_check_running\u001b[49m\u001b[43m(\u001b[49m\u001b[43m)\u001b[49m\n\u001b[0;32m    665\u001b[0m new_task \u001b[38;5;241m=\u001b[39m \u001b[38;5;129;01mnot\u001b[39;00m futures\u001b[38;5;241m.\u001b[39misfuture(future)\n\u001b[0;32m    666\u001b[0m future \u001b[38;5;241m=\u001b[39m tasks\u001b[38;5;241m.\u001b[39mensure_future(future, loop\u001b[38;5;241m=\u001b[39m\u001b[38;5;28mself\u001b[39m)\n",
      "File \u001b[1;32mc:\\Users\\TP23018\\AppData\\Local\\Programs\\Python\\Python312\\Lib\\asyncio\\base_events.py:622\u001b[0m, in \u001b[0;36mBaseEventLoop._check_running\u001b[1;34m(self)\u001b[0m\n\u001b[0;32m    620\u001b[0m \u001b[38;5;28;01mdef\u001b[39;00m \u001b[38;5;21m_check_running\u001b[39m(\u001b[38;5;28mself\u001b[39m):\n\u001b[0;32m    621\u001b[0m     \u001b[38;5;28;01mif\u001b[39;00m \u001b[38;5;28mself\u001b[39m\u001b[38;5;241m.\u001b[39mis_running():\n\u001b[1;32m--> 622\u001b[0m         \u001b[38;5;28;01mraise\u001b[39;00m \u001b[38;5;167;01mRuntimeError\u001b[39;00m(\u001b[38;5;124m'\u001b[39m\u001b[38;5;124mThis event loop is already running\u001b[39m\u001b[38;5;124m'\u001b[39m)\n\u001b[0;32m    623\u001b[0m     \u001b[38;5;28;01mif\u001b[39;00m events\u001b[38;5;241m.\u001b[39m_get_running_loop() \u001b[38;5;129;01mis\u001b[39;00m \u001b[38;5;129;01mnot\u001b[39;00m \u001b[38;5;28;01mNone\u001b[39;00m:\n\u001b[0;32m    624\u001b[0m         \u001b[38;5;28;01mraise\u001b[39;00m \u001b[38;5;167;01mRuntimeError\u001b[39;00m(\n\u001b[0;32m    625\u001b[0m             \u001b[38;5;124m'\u001b[39m\u001b[38;5;124mCannot run the event loop while another loop is running\u001b[39m\u001b[38;5;124m'\u001b[39m)\n",
      "\u001b[1;31mRuntimeError\u001b[0m: This event loop is already running"
     ]
    },
    {
     "name": "stdout",
     "output_type": "stream",
     "text": [
      "function1 start\n"
     ]
    }
   ],
   "source": [
    "loop = asyncio.get_event_loop()\n",
    "loop.create_task(asyncFunction(1, 3))\n",
    "loop.run_until_complete(asyncFunction(2, 3))"
   ]
  }
 ],
 "metadata": {
  "kernelspec": {
   "display_name": "Python 3",
   "language": "python",
   "name": "python3"
  },
  "language_info": {
   "codemirror_mode": {
    "name": "ipython",
    "version": 3
   },
   "file_extension": ".py",
   "mimetype": "text/x-python",
   "name": "python",
   "nbconvert_exporter": "python",
   "pygments_lexer": "ipython3",
   "version": "3.12.3"
  }
 },
 "nbformat": 4,
 "nbformat_minor": 2
}
